Workbook

Sheet Problem 9
A1: Problem 9 – Morley Properties Decision Analysis
A3: Payoff Matrix ($1000s)
A4: Size of Development | B4: Low | C4: Medium | D4: High
A5: Small | B5: 400 | C5: 400 | D5: 400
A6: Medium | B6: 200 | C6: 500 | D6: 500
A7: Large | B7: -400 | C7: 300 | D7: 800
A9: Probabilities | B9: 0.2175 | C9: 0.355 | D9: 0.4275
A11: a) Maximin Decision Rule
A12: Size of Development | B12: Low | C12: Medium | D12: High | E12: Row Min
A13: Small | B13: =B5 -> 400 | C13: =C5 -> 400 | D13: =D5 -> 400 | E13: =MIN(B13:D13) -> 400
A14: Medium | B14: =B6 -> 200 | C14: =C6 -> 500 | D14: =D6 -> 500 | E14: =MIN(B14:D14) -> 200
A15: Large | B15: =B7 -> -400 | C15: =C7 -> 300 | D15: =D7 -> 800 | E15: =MIN(B15:D15) -> -400
A17: Decision: | B17: =INDEX(A13:A15,MATCH(MAX(E13:E15),E13:E15,0)) -> Small | C17: (Max of Row Minima)
A18: Maximin Value: | B18: =MAX(E13:E15) -> 400
A20: b) Minimax Regret Decision Rule
A21: Best Payoff per State: | B21: =MAX(B5:B7) -> 400 | C21: =MAX(C5:C7) -> 500 | D21: =MAX(D5:D7) -> 800
A23: Regret Matrix ($1000s)
A24: Size of Development | B24: Low | C24: Medium | D24: High | E24: Max Regret
A25: Small | B25: =B$21-B5 -> 0 | C25: =C$21-C5 -> 100 | D25: =D$21-D5 -> 400 | E25: =MAX(B25:D25) -> 400
A26: Medium | B26: =B$21-B6 -> 200 | C26: =C$21-C6 -> 0 | D26: =D$21-D6 -> 300 | E26: =MAX(B26:D26) -> 300
A27: Large | B27: =B$21-B7 -> 800 | C27: =C$21-C7 -> 200 | D27: =D$21-D7 -> 0 | E27: =MAX(B27:D27) -> 800
A29: Decision: | B29: =INDEX(A25:A27,MATCH(MIN(E25:E27),E25:E27,0)) -> Medium | C29: (Min of Max Regrets)
A30: Minimax Regret Value: | B30: =MIN(E25:E27) -> 300
A32: c) Maximax Decision Rule
A33: Size of Development | B33: Low | C33: Medium | D33: High | E33: Row Max
A34: Small | B34: =B5 -> 400 | C34: =C5 -> 400 | D34: =D5 -> 400 | E34: =MAX(B34:D34) -> 400
A35: Medium | B35: =B6 -> 200 | C35: =C6 -> 500 | D35: =D6 -> 500 | E35: =MAX(B35:D35) -> 500
A36: Large | B36: =B7 -> -400 | C36: =C7 -> 300 | D36: =D7 -> 800 | E36: =MAX(B36:D36) -> 800
A38: Decision: | B38: =INDEX(A34:A36,MATCH(MAX(E34:E36),E34:E36,0)) -> Large | C38: (Max of Row Maxima)
A39: Maximax Value: | B39: =MAX(E34:E36) -> 800
A41: d) Expected Monetary Value (EMV) Decision Rule
A42: Size of Development | B42: Low | C42: Medium | D42: High | E42: EMV
A43: Small | B43: =B5 -> 400 | C43: =C5 -> 400 | D43: =D5 -> 400 | E43: =SUMPRODUCT(B43:D43,$B$9:$D$9) -> 400
A44: Medium | B44: =B6 -> 200 | C44: =C6 -> 500 | D44: =D6 -> 500 | E44: =SUMPRODUCT(B44:D44,$B$9:$D$9) -> 434.75
A45: Large | B45: =B7 -> -400 | C45: =C7 -> 300 | D45: =D7 -> 800 | E45: =SUMPRODUCT(B45:D45,$B$9:$D$9) -> 361.5
A47: Decision: | B47: =INDEX(A43:A45,MATCH(MAX(E43:E45),E43:E45,0)) -> Medium | C47: (Max EMV)
A48: EMV Value: | B48: =MAX(E43:E45) -> 434.75
A50: e) Expected Opportunity Loss (EOL) Decision Rule
A51: Regret (Opportunity Loss) Matrix
A52: Size of Development | B52: Low | C52: Medium | D52: High | E52: EOL
...

Sheet P10. a,b,d,e, 
C1: a) Construct the conditional probability table
B2: Actual Demand | E2: P(Forecast)
A3: Forecasted Demand | B3: Low | C3: Medium | D3: High
A4: Low | B4: 0.16 | C4: 0.03 | D4: 0.01 | E4: =SUM(B4:D4) -> 0.2
A5: Medium | B5: 0.035 | C5: 0.28 | D5: 0.035 | E5: =SUM(B5:D5) -> 0.35
A6: High | B6: 0.0225 | C6: 0.045 | D6: 0.3825 | E6: =SUM(B6:D6) -> 0.45
A7: P(Actual) | B7: =SUM(B4:B6) -> 0.2175 | C7: =SUM(C4:C6) -> 0.355 | D7: =SUM(D4:D6) -> 0.4275 | E7: =SUM(B7:D7) -> 1
C8: Conditional Probabilities For
C9: Given Forecasted Demands
B10: Actual Demand | E10: Sum Check
A11: Forecasted Demand | B11: Low | C11: Medium | D11: High
A12: Low | B12: =B4/SUM(B4:D4) -> 0.8 | C12: =C4/SUM(B4:D4) -> 0.15 | D12: =D4/SUM(B4:D4) -> 0.05 | E12: =SUM(B12:D12) -> 1
A13: Medium | B13: =B5/SUM(B5:D5) -> 0.1 | C13: =C5/SUM(B5:D5) -> 0.8 | D13: =D5/SUM(B5:D5) -> 0.1 | E13: =SUM(B13:D13) -> 1
A14: High | B14: =B6/SUM(B6:D6) -> 0.05 | C14: =C6/SUM(B6:D6) -> 0.1 | D14: =D6/SUM(B6:D6) -> 0.85 | E14: =SUM(B14:D14) -> 1
A16: b) EMV of the optimal decision without the consultant's assistance
B17: Market Demand
A18: Size of Development | B18: Low | C18: Medium | D18: High | E18: EMV
A19: Small | B19: 400 | C19: 400 | D19: 400 | E19: =SUMPRODUCT(B19:D19,$B$22:$D$22) -> 400
A20: Medium | B20: 200 | C20: 500 | D20: 500 | E20: =SUMPRODUCT(B20:D20,$B$22:$D$22) -> 434.75
A21: Large | B21: -400 | C21: 300 | D21: 800 | E21: =SUMPRODUCT(B21:D21,$B$22:$D$22) -> 361.5
A22: Probabilities | B22: =B7 -> 0.2175 | C22: =C7 -> 0.355 | D22: =D7 -> 0.4275
A24: Optimal Decision: | B24: =INDEX(A19:A21,MATCH(MAX(E19:E21),E19:E21,0)) -> Medium
A25: Maximum EMV: | B25: =MAX(E19:E21) -> 434.75
A26: (Payoffs in $1,000s)
A28: d) EMV of the optimal decision with the consultant's free assistance
A30: Forecast | B30: P(Forecast) | C30: Optimal Decision | D30: EMV Given Forecast
A31: Low | B31: =E4 -> 0.2 | C31: {=INDEX({"Small","Medium","Large"},'c) Tree diagram'!J23)} -> Small | D31: ='c) Tree diagram'!I24 -> 400
A32: Medium | B32: =E5 -> 0.35 | C32: {=INDEX({"Small","Medium","Large"},'c) Tree diagram'!J68)} -> Medium | D32: ='c) Tree diagram'!I69 -> 470
A33: High | B33: =E6 -> 0.45 | C33: {=INDEX({"Small","Medium","Large"},'c) Tree diagram'!J113)} -> Large | D33: ='c) Tree diagram'!I114 -> 690
A35: EMV with consultant: | B35: =SUMPRODUCT(B31:B33,D31:D33) -> 555 | C35: = 0.20×400 + 0.35×470 + 0.45×690
A37: e) Maximum price Morley Properties should be willing to pay the consultant
A39: EMV with consultant (from d): | B39: =B35 -> 555
A40: EMV without consultant (from b): | B40: =B25 -> 434.75
A42: EVSI (Expected Value of Sample Information): | B42: =B39-B40 -> 120.25
A44: Morley Properties should pay at most $120.25 thousand ($120,250) for the consultant.

Sheet c) Tree diagram
P1: ='P10. a,b,d,e, '!B12 -> 0.8
P2: Low Demand Occurs | Y2: Conditional Probabilities from part a.
S3: =SUM($P$4,$L$9,$H$24,$D$69) -> 400
P4: 400 | Q4: =$S$3 -> 400 | Y4: Probabilities of Low, Medium and High Forecasts can be ontained from Joint Probabilities table
P6: ='P10. a,b,d,e, '!C12 -> 0.15 | Y6: Payoffs from matrix on problem 9
L7: Build Small Development | P7: Med. Demand Occurs
S8: =SUM($P$9,$L$9,$H$24,$D$69) -> 400
L9: 0 | M9: =IF(ABS(1-SUM($P$1,$P$6,$P$11))<=0.00001,SUM($P$1*$Q$4,$P$6*$Q$9,$P$11*$Q$14),NA()) -> 400 | P9: 400 | Q9: =$S$8 -> 400
P11: ='P10. a,b,d,e, '!D12 -> 0.05
P12: High Demand Occurs
S13: =SUM($P$14,$L$9,$H$24,$D$69) -> 400
P14: 400 | Q14: =$S$13 -> 400
P16: ='P10. a,b,d,e, '!B12 -> 0.8
P17: Low Demand Occurs
S18: =SUM($P$19,$L$24,$H$24,$D$69) -> 200
P19: 200 | Q19: =$S$18 -> 200
H21: =SUM('P10. a,b,d,e, '!B4:D4) -> 0.2 | P21: ='P10. a,b,d,e, '!C12 -> 0.15
H22: Low Demand Forecast | L22: Build Med. Development | P22: Med. Demand Occurs
J23: =IF($I$24=$M$9,1,IF($I$24=$M$24,2,IF($I$24=$M$39,3))) -> 1 | S23: =SUM($P$24,$L$24,$H$24,$D$69) -> 500
H24: 0 | I24: =MAX($M$9,$M$24,$M$39) -> 400 | L24: 0 | M24: =IF(ABS(1-SUM($P$16,$P$21,$P$26))<=0.00001,SUM($P$16*$Q$19,$P$21*$Q$24,$P$26*$Q$29),NA()) -> 260 | P24: 500 | Q24: =$S$23 -> 500
P26: ='P10. a,b,d,e, '!D12 -> 0.05
P27: High Demand Occurs
S28: =SUM($P$29,$L$24,$H$24,$D$69) -> 500
P29: 500 | Q29: =$S$28 -> 500
P31: ='P10. a,b,d,e, '!B12 -> 0.8
P32: Low Demand Occurs
S33: =SUM($P$34,$L$39,$H$24,$D$69) -> -400
P34: -400 | Q34: =$S$33 -> -400
P36: ='P10. a,b,d,e, '!C12 -> 0.15
L37: Build Large Development | P37: Med. Demand Occurs
S38: =SUM($P$39,$L$39,$H$24,$D$69) -> 300
L39: 0 | M39: =IF(ABS(1-SUM($P$31,$P$36,$P$41))<=0.00001,SUM($P$31*$Q$34,$P$36*$Q$39,$P$41*$Q$44),NA()) -> -235 | P39: 300 | Q39: =$S$38 -> 300
P41: ='P10. a,b,d,e, '!D12 -> 0.05
P42: High Demand Occurs
S43: =SUM($P$44,$L$39,$H$24,$D$69) -> 800
P44: 800 | Q44: =$S$43 -> 800
P46: ='P10. a,b,d,e, '!B13 -> 0.1
P47: Low Demand Occurs
S48: =SUM($P$49,$L$54,$H$69,$D$69) -> 400
P49: 400 | Q49: =$S$48 -> 400
...

Sheet Problem 11
A1: Problem 11 – Refer to Question 9. Morley Properties Utility Analysis
A3: Utility Function (exponential): | B3: U(x) = 1 − e^(−x/R)
A4: Risk Tolerance R = | B4: 100 | C4: (in $1,000s) → so payoffs are already in $1,000s
A6: Original Payoff Matrix ($1,000s)
A7: Size of Development | B7: Low | C7: Medium | D7: High
A8: Small | B8: ='Problem 9'!B5 -> 400 | C8: ='Problem 9'!C5 -> 400 | D8: ='Problem 9'!D5 -> 400
A9: Medium | B9: ='Problem 9'!B6 -> 200 | C9: ='Problem 9'!C6 -> 500 | D9: ='Problem 9'!D6 -> 500
A10: Large | B10: ='Problem 9'!B7 -> -400 | C10: ='Problem 9'!C7 -> 300 | D10: ='Problem 9'!D7 -> 800
A11: Probabilities | B11: ='Problem 9'!B9 -> 0.2175 | C11: ='Problem 9'!C9 -> 0.355 | D11: ='Problem 9'!D9 -> 0.4275
A13: a) Utility Payoff Matrix [U(x) = 1 − e^(−x/R), R = 100]
A14: Size of Development | B14: Low | C14: Medium | D14: High
A15: Small | B15: =1-EXP(-B8/$B$4) -> 0.98168436 | C15: =1-EXP(-C8/$B$4) -> 0.98168436 | D15: =1-EXP(-D8/$B$4) -> 0.98168436
A16: Medium | B16: =1-EXP(-B9/$B$4) -> 0.86466472 | C16: =1-EXP(-C9/$B$4) -> 0.99326205 | D16: =1-EXP(-D9/$B$4) -> 0.99326205
A17: Large | B17: =1-EXP(-B10/$B$4) -> -53.59815 | C17: =1-EXP(-C10/$B$4) -> 0.95021293 | D17: =1-EXP(-D10/$B$4) -> 0.99966454
A19: b) Expected Utility (EU) Decision
A20: Size of Development | B20: Low | C20: Medium | D20: High | E20: EU
A21: Small | B21: =B15 -> 0.98168436 | C21: =C15 -> 0.98168436 | D21: =D15 -> 0.98168436 | E21: =SUMPRODUCT(B21:D21,$B$11:$D$11) -> 0.98168436
A22: Medium | B22: =B16 -> 0.86466472 | C22: =C16 -> 0.99326205 | D22: =D16 -> 0.99326205 | E22: =SUMPRODUCT(B22:D22,$B$11:$D$11) -> 0.96529213
A23: Large | B23: =B17 -> -53.59815 | C23: =C17 -> 0.95021293 | D23: =D17 -> 0.99966454 | E23: =SUMPRODUCT(B23:D23,$B$11:$D$11) -> -10.892915
A25: Decision: | B25: =INDEX(A21:A23,MATCH(MAX(E21:E23),E21:E23,0)) -> Small | C25: (Max Expected Utility)
A26: Maximum EU: | B26: =MAX(E21:E23) -> 0.98168436
A28: Interpretation:
A29: Unlike EMV (which chose Medium), utility analysis chooses Small because
A30: the owner is highly risk-averse. The catastrophic loss of $400K from Large
A31: yields U(−400) = −53.60, which heavily penalizes that alternative.
A32: Small guarantees U = 0.9817 regardless of demand — the safest outcome.
